<sdf version='1.7'>
  <world name='default'>
    <gui fullscreen='0'>
      <camera name='user_camera'>
        <pose>0 5 1 0 0.2 -1.5707</pose>
        <view_controller>orbit</view_controller>
        <projection_type>perspective</projection_type>
      </camera>
      <plugin name='keyboard' filename='libKeyboardGUIPlugin.so'/>
    </gui>
    <physics type='ode'>
      <ode>
        <solver>
          <type>quick</type>
          <iters>100</iters>
          <sor>1</sor>
          <use_dynamic_moi_rescaling>0</use_dynamic_moi_rescaling>
        </solver>
        <constraints>
          <cfm>0</cfm>
          <erp>0.2</erp>
          <contact_max_correcting_vel>0.1</contact_max_correcting_vel>
          <contact_surface_layer>0</contact_surface_layer>
        </constraints>
      </ode>
      <real_time_update_rate>400</real_time_update_rate>
      <max_step_size>0.0025</max_step_size>
      <real_time_factor>1</real_time_factor>
    </physics>
    <light name='sun' type='directional'>
      <cast_shadows>1</cast_shadows>
      <pose>0 0 10 0 -0 0</pose>
      <diffuse>0.8 0.8 0.8 1</diffuse>
      <specular>0.2 0.2 0.2 1</specular>
      <attenuation>
        <range>1000</range>
        <constant>0.9</constant>
        <linear>0.01</linear>
        <quadratic>0.001</quadratic>
      </attenuation>
      <direction>-0.5 0.1 -0.9</direction>
      <spot>
        <inner_angle>0</inner_angle>
        <outer_angle>0</outer_angle>
        <falloff>0</falloff>
      </spot>
    </light>
    <model name='ground_plane'>
      <static>1</static>
      <link name='link'>
        <collision name='collision'>
          <geometry>
            <plane>
              <normal>0 0 1</normal>
              <size>5000 5000</size>
            </plane>
          </geometry>
          <surface>
            <friction>
              <ode>
                <mu>1</mu>
                <mu2>1</mu2>
              </ode>
              <torsional>
                <ode/>
              </torsional>
            </friction>
            <contact>
              <ode/>
            </contact>
            <bounce/>
          </surface>
          <max_contacts>10</max_contacts>
        </collision>
        <visual name='runway'>
          <pose>0 0 0.005 0 0 -1.5707</pose>
          <cast_shadows>0</cast_shadows>
          <geometry>
            <plane>
              <normal>0 0 1</normal>
              <size>1829 45</size>
            </plane>
          </geometry>
          <material>
            <script>
              <uri>file://media/materials/scripts/gazebo.material</uri>
              <name>Gazebo/Runway</name>
            </script>
          </material>
        </visual>
        <visual name='grass'>
          <pose>0 0 -0.1 0 -0 0</pose>
          <cast_shadows>0</cast_shadows>
          <geometry>
            <plane>
              <normal>0 0 1</normal>
              <size>5000 5000</size>
            </plane>
          </geometry>
          <material>
            <script>
              <uri>file://media/materials/scripts/gazebo.material</uri>
              <name>Gazebo/Grass</name>
            </script>
          </material>
        </visual>
        <self_collide>0</self_collide>
        <enable_wind>0</enable_wind>
        <kinematic>0</kinematic>
      </link>
    </model>
    <gravity>0 0 -9.8</gravity>
    <magnetic_field>6e-06 2.3e-05 -4.2e-05</magnetic_field>
    <atmosphere type='adiabatic'/>
    <scene>
      <ambient>0.4 0.4 0.4 1</ambient>
      <background>0.7 0.7 0.7 1</background>
      <shadows>1</shadows>
    </scene>
    <wind/>
    <spherical_coordinates>
      <surface_model>EARTH_WGS84</surface_model>
      <latitude_deg>0</latitude_deg>
      <longitude_deg>0</longitude_deg>
      <elevation>0</elevation>
      <heading_deg>0</heading_deg>
    </spherical_coordinates>
    <model name='zephyr_delta_wing_demo'>
      <pose>-0.027856 0.102507 0 0 -0 0</pose>
      <frame name='zephyr_delta_wing::__model__' attached_to='zephyr_delta_wing::wing'>
        <pose relative_to='__model__'>0 0 0.2 0 -0 0</pose>
      </frame>
      <link name='zephyr_delta_wing::wing'>
        <inertial>
          <pose>0 -0.12 0 0 -0 0</pose>
          <mass>1.5</mass>
          <inertia>
            <ixx>0.0831371</ixx>
            <ixy>0</ixy>
            <iyy>0.387382</iyy>
            <ixz>0</ixz>
            <iyz>0</iyz>
            <izz>0.469845</izz>
          </inertia>
        </inertial>
        <visual name='visual'>
          <geometry>
            <mesh>
              <uri>model://zephyr_delta_wing/meshes/wing.dae</uri>
              <submesh>
                <name>Wing</name>
                <center>1</center>
              </submesh>
            </mesh>
          </geometry>
        </visual>
        <collision name='body_collision'>
          <geometry>
            <mesh>
              <uri>model://zephyr_delta_wing/meshes/wing.dae</uri>
              <submesh>
                <name>Wing</name>
                <center>1</center>
              </submesh>
            </mesh>
          </geometry>
          <max_contacts>10</max_contacts>
          <surface>
            <contact>
              <ode/>
            </contact>
            <bounce/>
            <friction>
              <torsional>
                <ode/>
              </torsional>
              <ode/>
            </friction>
          </surface>
        </collision>
        <collision name='right_rudder_collision'>
          <pose>-0.76435 0.33918 0.002 -0.03 0 0</pose>
          <geometry>
            <box>
              <size>0.005 0.12993 0.12688</size>
            </box>
          </geometry>
          <max_contacts>10</max_contacts>
          <surface>
            <contact>
              <ode/>
            </contact>
            <bounce/>
            <friction>
              <torsional>
                <ode/>
              </torsional>
              <ode/>
            </friction>
          </surface>
        </collision>
        <collision name='left_rudder_collision'>
          <pose>0.76435 0.33918 0.002 -0.03 0 0</pose>
          <geometry>
            <box>
              <size>0.005 0.12993 0.12688</size>
            </box>
          </geometry>
          <max_contacts>10</max_contacts>
          <surface>
            <contact>
              <ode/>
            </contact>
            <bounce/>
            <friction>
              <torsional>
                <ode/>
              </torsional>
              <ode/>
            </friction>
          </surface>
        </collision>
        <pose relative_to='zephyr_delta_wing::__model__'>0 0 0 0 -0 0</pose>
        <self_collide>0</self_collide>
        <enable_wind>0</enable_wind>
        <kinematic>0</kinematic>
      </link>
      <link name='zephyr_delta_wing::zephyr/imu_link'>
        <inertial>
          <pose>0 0 0 0 -0 0</pose>
          <mass>0.15</mass>
          <inertia>
            <ixx>1e-05</ixx>
            <ixy>0</ixy>
            <ixz>0</ixz>
            <iyy>2e-05</iyy>
            <iyz>0</iyz>
            <izz>2e-05</izz>
          </inertia>
        </inertial>
        <sensor name='imu_sensor' type='imu'>
          <pose>0 0 0 -3.14159 -0 -1.57079</pose>
          <always_on>1</always_on>
          <update_rate>1000</update_rate>
          <imu/>
        </sensor>
        <pose relative_to='zephyr_delta_wing::__model__'>0 0 0 0 -0 0</pose>
        <self_collide>0</self_collide>
        <enable_wind>0</enable_wind>
        <kinematic>0</kinematic>
      </link>
      <joint name='zephyr_delta_wing::zephyr/imu_joint' type='revolute'>
        <child>zephyr_delta_wing::zephyr/imu_link</child>
        <parent>zephyr_delta_wing::wing</parent>
        <axis>
          <xyz expressed_in='zephyr_delta_wing::__model__'>0 0 1</xyz>
          <limit>
            <lower>0</lower>
            <upper>0</upper>
            <effort>0</effort>
            <velocity>0</velocity>
          </limit>
          <dynamics>
            <damping>1</damping>
            <spring_reference>0</spring_reference>
            <spring_stiffness>0</spring_stiffness>
          </dynamics>
        </axis>
        <physics>
          <ode>
            <implicit_spring_damper>1</implicit_spring_damper>
            <limit>
              <cfm>0</cfm>
              <erp>0.2</erp>
            </limit>
          </ode>
        </physics>
      </joint>
      <link name='zephyr_delta_wing::propeller'>
        <pose relative_to='zephyr_delta_wing::__model__'>0 0.07 0.008 0 1.57079 0</pose>
        <inertial>
          <mass>0.05</mass>
          <inertia>
            <ixx>0.000367571</ixx>
            <ixy>0</ixy>
            <iyy>0.00036985</iyy>
            <ixz>0</ixz>
            <iyz>0</iyz>
            <izz>3.187e-06</izz>
          </inertia>
          <pose>0 0 0 0 -0 0</pose>
        </inertial>
        <visual name='visual'>
          <geometry>
            <mesh>
              <uri>model://zephyr_delta_wing/meshes/wing.dae</uri>
              <submesh>
                <name>Propeller</name>
                <center>1</center>
              </submesh>
            </mesh>
          </geometry>
        </visual>
        <collision name='blade1'>
          <pose>0 0 0.074205 0 -0 0.3</pose>
          <geometry>
            <box>
              <size>0.02561 0.00541 0.14841</size>
            </box>
          </geometry>
          <max_contacts>10</max_contacts>
          <surface>
            <contact>
              <ode/>
            </contact>
            <bounce/>
            <friction>
              <torsional>
                <ode/>
              </torsional>
              <ode/>
            </friction>
          </surface>
        </collision>
        <collision name='blade2'>
          <pose>0 0 -0.074205 0 0 -0.3</pose>
          <geometry>
            <box>
              <size>0.02561 0.00541 0.14841</size>
            </box>
          </geometry>
          <max_contacts>10</max_contacts>
          <surface>
            <contact>
              <ode/>
            </contact>
            <bounce/>
            <friction>
              <torsional>
                <ode/>
              </torsional>
              <ode/>
            </friction>
          </surface>
        </collision>
        <self_collide>0</self_collide>
        <enable_wind>0</enable_wind>
        <kinematic>0</kinematic>
      </link>
      <link name='zephyr_delta_wing::flap_left'>
        <pose relative_to='zephyr_delta_wing::__model__'>0.453 0.239 0.007 0 -0 0</pose>
        <inertial>
          <pose>0 0 0 0 -0 0.324457</pose>
          <mass>0.1</mass>
          <inertia>
            <ixx>0.000102319</ixx>
            <ixy>0</ixy>
            <iyy>0.00334417</iyy>
            <ixz>0</ixz>
            <iyz>0</iyz>
            <izz>0.00344607</izz>
          </inertia>
        </inertial>
        <visual name='visual'>
          <geometry>
            <mesh>
              <uri>model://zephyr_delta_wing/meshes/wing.dae</uri>
              <submesh>
                <name>Flap_Left</name>
                <center>1</center>
              </submesh>
            </mesh>
          </geometry>
        </visual>
        <collision name='collision'>
          <pose>-0.01 0.01 0 0 -0 0.324457</pose>
          <geometry>
            <box>
              <size>0.633463 0.110694 0.005</size>
            </box>
          </geometry>
          <max_contacts>10</max_contacts>
          <surface>
            <contact>
              <ode/>
            </contact>
            <bounce/>
            <friction>
              <torsional>
                <ode/>
              </torsional>
              <ode/>
            </friction>
          </surface>
        </collision>
        <self_collide>0</self_collide>
        <enable_wind>0</enable_wind>
        <kinematic>0</kinematic>
      </link>
      <link name='zephyr_delta_wing::flap_right'>
        <pose relative_to='zephyr_delta_wing::__model__'>-0.453 0.239 0.007 0 -0 0</pose>
        <inertial>
          <pose>0 0 0 0 0 -0.324457</pose>
          <mass>0.1</mass>
          <inertia>
            <ixx>0.000102319</ixx>
            <ixy>0</ixy>
            <iyy>0.00334417</iyy>
            <ixz>0</ixz>
            <iyz>0</iyz>
            <izz>0.00344607</izz>
          </inertia>
        </inertial>
        <visual name='visual'>
          <geometry>
            <mesh>
              <uri>model://zephyr_delta_wing/meshes/wing.dae</uri>
              <submesh>
                <name>Flap_Right</name>
                <center>1</center>
              </submesh>
            </mesh>
          </geometry>
        </visual>
        <collision name='collision'>
          <pose>0.01 0.01 0 0 0 -0.324457</pose>
          <geometry>
            <box>
              <size>0.633463 0.110694 0.005</size>
            </box>
          </geometry>
          <max_contacts>10</max_contacts>
          <surface>
            <contact>
              <ode/>
            </contact>
            <bounce/>
            <friction>
              <torsional>
                <ode/>
              </torsional>
              <ode/>
            </friction>
          </surface>
        </collision>
        <self_collide>0</self_collide>
        <enable_wind>0</enable_wind>
        <kinematic>0</kinematic>
      </link>
      <joint name='zephyr_delta_wing::propeller_joint' type='revolute'>
        <parent>zephyr_delta_wing::wing</parent>
        <child>zephyr_delta_wing::propeller</child>
        <axis>
          <xyz>0 -1 0</xyz>
          <dynamics>
            <damping>0.002</damping>
            <spring_reference>0</spring_reference>
            <spring_stiffness>0</spring_stiffness>
          </dynamics>
          <limit>
            <lower>-1e+16</lower>
            <upper>1e+16</upper>
          </limit>
        </axis>
        <physics>
          <ode>
            <implicit_spring_damper>1</implicit_spring_damper>
            <limit>
              <cfm>0</cfm>
              <erp>0.2</erp>
            </limit>
          </ode>
        </physics>
      </joint>
      <joint name='zephyr_delta_wing::flap_left_joint' type='revolute'>
        <parent>zephyr_delta_wing::wing</parent>
        <child>zephyr_delta_wing::flap_left</child>
        <pose>0 -0.04 0 0 -0 0</pose>
        <axis>
          <xyz>1 0.330321 0</xyz>
          <limit>
            <lower>-0.524</lower>
            <upper>0.524</upper>
          </limit>
          <dynamics>
            <damping>0.1</damping>
            <spring_reference>0</spring_reference>
            <spring_stiffness>0</spring_stiffness>
          </dynamics>
        </axis>
        <physics>
          <ode>
            <implicit_spring_damper>1</implicit_spring_damper>
            <limit>
              <cfm>0</cfm>
              <erp>0.2</erp>
            </limit>
          </ode>
        </physics>
      </joint>
      <joint name='zephyr_delta_wing::flap_right_joint' type='revolute'>
        <parent>zephyr_delta_wing::wing</parent>
        <child>zephyr_delta_wing::flap_right</child>
        <pose>0 -0.04 0 0 -0 0</pose>
        <axis>
          <xyz>1 -0.330321 0</xyz>
          <limit>
            <lower>-0.524</lower>
            <upper>0.524</upper>
          </limit>
          <dynamics>
            <damping>0.1</damping>
            <spring_reference>0</spring_reference>
            <spring_stiffness>0</spring_stiffness>
          </dynamics>
        </axis>
        <physics>
          <ode>
            <implicit_spring_damper>1</implicit_spring_damper>
            <limit>
              <cfm>0</cfm>
              <erp>0.2</erp>
            </limit>
          </ode>
        </physics>
      </joint>
      <plugin name='invisible_canard' filename='libLiftDragPlugin.so'>
        <a0>0.13</a0>
        <cla>3.7</cla>
        <cda>0.06417112299</cda>
        <cma>-1.8</cma>
        <alpha_stall>0.3391428111</alpha_stall>
        <cla_stall>-3.85</cla_stall>
        <cda_stall>-0.9233984055</cda_stall>
        <cma_stall>0</cma_stall>
        <cp>0 -0.1 0</cp>
        <area>0.50</area>
        <air_density>1.2041</air_density>
        <forward>0 -1 0</forward>
        <upward>0 0 1</upward>
        <link_name>zephyr_delta_wing::wing</link_name>
      </plugin>
      <plugin name='left_wing' filename='libLiftDragPlugin.so'>
        <a0>0.15</a0>
        <cla>6.8</cla>
        <cda>0.06417112299</cda>
        <cma>-1.8</cma>
        <alpha_stall>0.6391428111</alpha_stall>
        <cla_stall>-3.85</cla_stall>
        <cda_stall>-0.9233984055</cda_stall>
        <cma_stall>0</cma_stall>
        <cp>0.7 0.20 0</cp>
        <area>0.10</area>
        <air_density>1.2041</air_density>
        <forward>0 -1 0</forward>
        <upward>0 0 1</upward>
        <link_name>zephyr_delta_wing::wing</link_name>
        <control_joint_name>zephyr_delta_wing::flap_left_joint</control_joint_name>
        <control_joint_rad_to_cl>-5.0</control_joint_rad_to_cl>
      </plugin>
      <plugin name='right_wing' filename='libLiftDragPlugin.so'>
        <a0>0.15</a0>
        <cla>6.8</cla>
        <cda>0.06417112299</cda>
        <cma>-1.8</cma>
        <alpha_stall>0.6391428111</alpha_stall>
        <cla_stall>-3.85</cla_stall>
        <cda_stall>-0.9233984055</cda_stall>
        <cma_stall>0</cma_stall>
        <cp>-0.7 0.20 0</cp>
        <area>0.10</area>
        <air_density>1.2041</air_density>
        <forward>0 -1 0</forward>
        <upward>0 0 1</upward>
        <link_name>zephyr_delta_wing::wing</link_name>
        <control_joint_name>zephyr_delta_wing::flap_right_joint</control_joint_name>
        <control_joint_rad_to_cl>-5.0</control_joint_rad_to_cl>
      </plugin>
      <plugin name='left_rudder' filename='libLiftDragPlugin.so'>
        <a0>0.0</a0>
        <cla>4.752798721</cla>
        <cda>0.6417112299</cda>
        <cma>-1.8</cma>
        <alpha_stall>0.3391428111</alpha_stall>
        <cla_stall>-3.85</cla_stall>
        <cda_stall>-0.9233984055</cda_stall>
        <cma_stall>0</cma_stall>
        <cp>-0.76 0.30 0.025</cp>
        <area>0.12</area>
        <air_density>1.2041</air_density>
        <forward>0 -1 0</forward>
        <upward>1 0 0</upward>
        <link_name>zephyr_delta_wing::wing</link_name>
      </plugin>
      <plugin name='right_rudder' filename='libLiftDragPlugin.so'>
        <a0>0.0</a0>
        <cla>4.752798721</cla>
        <cda>0.6417112299</cda>
        <cma>-1.8</cma>
        <alpha_stall>0.3391428111</alpha_stall>
        <cla_stall>-3.85</cla_stall>
        <cda_stall>-0.9233984055</cda_stall>
        <cma_stall>0</cma_stall>
        <cp>0.76 0.30 0.025</cp>
        <area>0.12</area>
        <air_density>1.2041</air_density>
        <forward>0 -1 0</forward>
        <upward>1 0 0</upward>
        <link_name>zephyr_delta_wing::wing</link_name>
      </plugin>
      <plugin name='propeller_blade_1' filename='libLiftDragPlugin.so'>
        <a0>0.30</a0>
        <alpha_stall>1.4</alpha_stall>
        <cla>4.2500</cla>
        <cda>0.10</cda>
        <cma>0.00</cma>
        <cla_stall>-0.025</cla_stall>
        <cda_stall>0.0</cda_stall>
        <cma_stall>0.0</cma_stall>
        <area>0.02</area>
        <air_density>1.2041</air_density>
        <cp>0 0 0.074205</cp>
        <forward>-1 0 0</forward>
        <upward>0 -1 0</upward>
        <link_name>zephyr_delta_wing::propeller</link_name>
      </plugin>
      <plugin name='propeller_blade_2' filename='libLiftDragPlugin.so'>
        <a0>0.30</a0>
        <alpha_stall>1.4</alpha_stall>
        <cla>4.2500</cla>
        <cda>0.10</cda>
        <cma>0.00</cma>
        <cla_stall>-0.025</cla_stall>
        <cda_stall>0.0</cda_stall>
        <cma_stall>0.0</cma_stall>
        <area>0.02</area>
        <air_density>1.2041</air_density>
        <cp>0 0 -0.074205</cp>
        <forward>1 0 0</forward>
        <upward>0 -1 0</upward>
        <link_name>zephyr_delta_wing::propeller</link_name>
      </plugin>
      <frame name='ZED_stereocamera::__model__' attached_to='ZED_stereocamera::link'>
        <pose relative_to='__model__'>0 -0.34 0.28 0 -0 -1.5708</pose>
      </frame>
      <link name='ZED_stereocamera::link'>
        <pose relative_to='ZED_stereocamera::__model__'>0 0 0 0 -0 0</pose>
        <inertial>
          <mass>0.159</mass>
          <inertia>
            <ixx>1.2e-05</ixx>
            <iyy>0.000406</iyy>
            <izz>0.000418</izz>
            <ixy>0</ixy>
            <ixz>0</ixz>
            <iyz>0</iyz>
          </inertia>
          <pose>0 0 0 0 -0 0</pose>
        </inertial>
        <collision name='collision'>
          <geometry>
            <box>
              <size>0.1 0.1 0.1</size>
            </box>
          </geometry>
          <max_contacts>10</max_contacts>
          <surface>
            <contact>
              <ode/>
            </contact>
            <bounce/>
            <friction>
              <torsional>
                <ode/>
              </torsional>
              <ode/>
            </friction>
          </surface>
        </collision>
        <visual name='visual'>
          <geometry>
            <mesh>
              <uri>model://ZED_stereocamera/meshes/ZED.stl</uri>
            </mesh>
          </geometry>
          <material>
            <script>
              <name>Gazebo/Grey</name>
              <uri>__default__</uri>
            </script>
          </material>
        </visual>
        <visual name='visual_lens_left'>
          <pose>0 -0.06 0 0 1.57 0</pose>
          <geometry>
            <cylinder>
              <radius>0.007</radius>
              <length>0.03</length>
            </cylinder>
          </geometry>
          <material>
            <script>
              <uri>file://media/materials/scripts/gazebo.material</uri>
              <name>Gazebo/WideLensMap</name>
            </script>
          </material>
        </visual>
        <visual name='visual_lens_right'>
          <pose>0 0.06 0 0 1.57 0</pose>
          <geometry>
            <cylinder>
              <radius>0.007</radius>
              <length>0.03</length>
            </cylinder>
          </geometry>
          <material>
            <script>
              <uri>file://media/materials/scripts/gazebo.material</uri>
              <name>Gazebo/WideLensMap</name>
            </script>
          </material>
        </visual>
        <sensor name='camera' type='multicamera'>
          <always_on>1</always_on>
          <update_rate>30</update_rate>
          <visualize>1</visualize>
          <camera name='left'>
            <pose>0 0 0 0 -0 0</pose>
            <horizontal_fov>1.91986</horizontal_fov>
            <image>
              <width>720</width>
              <height>480</height>
            </image>
            <clip>
              <near>0.1</near>
              <far>100</far>
            </clip>
          </camera>
          <camera name='right'>
            <pose>0 -0.12 0 0 -0 0</pose>
            <horizontal_fov>1.91986</horizontal_fov>
            <image>
              <width>720</width>
              <height>480</height>
            </image>
            <clip>
              <near>0.1</near>
              <far>100</far>
            </clip>
          </camera>
        </sensor>
        <self_collide>0</self_collide>
        <enable_wind>0</enable_wind>
        <kinematic>0</kinematic>
      </link>
      <link name='cam_link'>
        <pose>0 0 0 0 -0 0</pose>
        <inertial>
          <mass>0.01</mass>
          <inertia>
            <ixx>0.0001</ixx>
            <iyy>0.0001</iyy>
            <izz>0.0001</izz>
            <ixy>0</ixy>
            <ixz>0</ixz>
            <iyz>0</iyz>
          </inertia>
          <pose>0 0 0 0 -0 0</pose>
        </inertial>
        <sensor name='chase_cam_wide' type='camera'>
          <pose>0 2 1 -0 0.2 -1.5717</pose>
          <camera>
            <horizontal_fov>1.5</horizontal_fov>
            <image>
              <width>1920</width>
              <height>1080</height>
            </image>
            <clip>
              <near>0.1</near>
              <far>1000</far>
            </clip>
          </camera>
          <always_on>0</always_on>
          <update_rate>60</update_rate>
          <visualize>0</visualize>
        </sensor>
        <self_collide>0</self_collide>
        <enable_wind>0</enable_wind>
        <kinematic>0</kinematic>
      </link>
      <joint name='camera_mount' type='fixed'>
        <child>ZED_stereocamera::link</child>
        <parent>zephyr_delta_wing::wing</parent>
        <axis>
          <xyz>0 0 1</xyz>
          <limit>
            <upper>0</upper>
            <lower>0</lower>
          </limit>
        </axis>
      </joint>
      <joint name='virtual_camera_mount' type='fixed'>
        <child>cam_link</child>
        <parent>zephyr_delta_wing::wing</parent>
        <axis>
          <xyz>0 0 1</xyz>
          <limit>
            <upper>0</upper>
            <lower>0</lower>
          </limit>
        </axis>
      </joint>
      <link name='skid_pad'>
        <pose>0 -0.07 -0.02 0 -0 0</pose>
        <inertial>
          <mass>0.1</mass>
          <inertia>
            <ixx>0.00431371</ixx>
            <ixy>0</ixy>
            <iyy>0.00387382</iyy>
            <ixz>0</ixz>
            <iyz>0</iyz>
            <izz>0.00809845</izz>
          </inertia>
          <pose>0 0 0 0 -0 0</pose>
        </inertial>
        <collision name='skid_pad'>
          <pose>0 0 0 0 -0 0</pose>
          <geometry>
            <box>
              <size>1 0.5 0.05</size>
            </box>
          </geometry>
          <surface>
            <contact>
              <ode>
                <kp>100000</kp>
                <kd>1</kd>
                <min_depth>0.01</min_depth>
                <max_vel>1</max_vel>
              </ode>
            </contact>
            <friction>
              <ode>
                <mu>0.3</mu>
                <fdir1>0 1 0</fdir1>
              </ode>
              <torsional>
                <ode/>
              </torsional>
            </friction>
            <bounce/>
          </surface>
          <max_contacts>10</max_contacts>
        </collision>
        <self_collide>0</self_collide>
        <enable_wind>0</enable_wind>
        <kinematic>0</kinematic>
      </link>
      <joint name='skid_pad_joint' type='fixed'>
        <parent>zephyr_delta_wing::wing</parent>
        <child>skid_pad</child>
        <axis>
          <limit>
            <lower>0</lower>
            <upper>0</upper>
          </limit>
          <xyz expressed_in='__model__'>0 1 0</xyz>
        </axis>
      </joint>
      <plugin name='ardupilot_plugin' filename='libArduPilotPlugin.so'>
        <fdm_addr>127.0.0.1</fdm_addr>
        <fdm_port_in>9002</fdm_port_in>
        <fdm_port_out>9003</fdm_port_out>
        <modelXYZToAirplaneXForwardZDown>0 0 0 3.141593 0 -1.57079</modelXYZToAirplaneXForwardZDown>
        <gazeboXYZToNED>0 0 0 3.141593 0 -1.57079</gazeboXYZToNED>
        <imuName>zephyr_delta_wing_demo::zephyr_delta_wing::zephyr/imu_link::imu_sensor</imuName>
        <connectionTimeoutMaxCount>5</connectionTimeoutMaxCount>
        <control channel='2'>
          <multiplier>838</multiplier>
          <offset>0.2</offset>
          <type>VELOCITY</type>
          <p_gain>0.5</p_gain>
          <i_gain>0</i_gain>
          <d_gain>0</d_gain>
          <i_max>0</i_max>
          <i_min>0</i_min>
          <cmd_max>2.0</cmd_max>
          <cmd_min>0.0</cmd_min>
          <jointName>zephyr_delta_wing::propeller_joint</jointName>
        </control>
        <control channel='0'>
          <multiplier>-1</multiplier>
          <offset>-0.5</offset>
          <type>POSITION</type>
          <p_gain>10.0</p_gain>
          <i_gain>0</i_gain>
          <d_gain>0</d_gain>
          <i_max>0</i_max>
          <i_min>0</i_min>
          <cmd_max>2.0</cmd_max>
          <cmd_min>-2.0</cmd_min>
          <jointName>zephyr_delta_wing::flap_left_joint</jointName>
        </control>
        <control channel='1'>
          <multiplier>-1</multiplier>
          <offset>-0.5</offset>
          <type>POSITION</type>
          <p_gain>10.0</p_gain>
          <i_gain>0</i_gain>
          <d_gain>0</d_gain>
          <i_max>0</i_max>
          <i_min>0</i_min>
          <cmd_max>2.0</cmd_max>
          <cmd_min>-2.0</cmd_min>
          <jointName>zephyr_delta_wing::flap_right_joint</jointName>
        </control>
      </plugin>
      <sensor name='gps_sensor' type='gps'>
        <pose>0 0 0 0 0 0</pose>
        <update_rate>10.0</update_rate>
        <always_on>1</always_on>
        <gps>
          <position_sensing>
            <horizontal>
              <noise type='gaussian_quantized'>
                <mean>0</mean>
                <stddev>1</stddev>
                <bias_mean>3</bias_mean>
                <bias_stddev>1</bias_stddev>
                <precision>0.5</precision>
              </noise>
            </horizontal>
            <vertical>
              <noise type='gaussian_quantized'>
                <mean>0</mean>
                <stddev>1</stddev>
                <bias_mean>3</bias_mean>
                <bias_stddev>1</bias_stddev>
                <precision>1.0</precision>
              </noise>
            </vertical>
          </position_sensing>
          <velocity_sensing>
            <horizontal>
              <noise type='gaussian_quantized'>
                <mean>0</mean>
                <stddev>0.1</stddev>
                <bias_mean>0.1</bias_mean>
                <bias_stddev>0.1</bias_stddev>
                <precision>0.1</precision>
              </noise>
            </horizontal>
            <vertical>
              <noise type='gaussian_quantized'>
                <mean>0</mean>
                <stddev>0.2</stddev>
                <bias_mean>0.2</bias_mean>
                <bias_stddev>0.2</bias_stddev>
                <precision>0.2</precision>
              </noise>
            </vertical>
          </velocity_sensing>
        </gps>
      </sensor>
    </model>
    <state world_name='default'>
      <sim_time>93 760000000</sim_time>
      <real_time>94 30144491</real_time>
      <wall_time>1658839968 480679264</wall_time>
      <iterations>37504</iterations>
      <model name='ground_plane'>
        <pose>0 0 0 0 -0 0</pose>
        <scale>1 1 1</scale>
        <link name='link'>
          <pose>0 0 0 0 -0 0</pose>
          <velocity>0 0 0 0 -0 0</velocity>
          <acceleration>0 0 0 0 -0 0</acceleration>
          <wrench>0 0 0 0 -0 0</wrench>
        </link>
      </model>
      <model name='zephyr_delta_wing_demo'>
        <pose>-0.027904 0.107178 0.034946 -1.5e-05 3e-06 6.9e-05</pose>
        <scale>1 1 1</scale>
        <link name='ZED_stereocamera::link'>
          <pose>-0.027879 -0.232817 0.314947 -3e-06 -1.5e-05 -1.57073</pose>
          <velocity>0.000766 0.000118 9.8e-05 -0.000504 0.00173 -3.6e-05</velocity>
          <acceleration>0.600986 0.018993 0.010907 -0.014148 0.613092 -0.023953</acceleration>
          <wrench>0.095557 0.00302 0.001734 0 -0 0</wrench>
        </link>
        <link name='cam_link'>
          <pose>-0.027904 0.107178 0.034946 -1.5e-05 3e-06 6.9e-05</pose>
          <velocity>-3.8e-05 -2.9e-05 -7.5e-05 -0.000504 0.00173 -3.6e-05</velocity>
          <acceleration>-0.025456 -0.092359 -0.129508 -0.383814 1.31782 -0.023597</acceleration>
          <wrench>-0.000255 -0.000924 -0.001295 0 -0 0</wrench>
        </link>
        <link name='skid_pad'>
          <pose>-0.027899 0.037166 0.01495 1e-05 -1.2e-05 6.9e-05</pose>
          <velocity>-0.000236 7.1e-05 -1.4e-05 -0.000476 -0.009517 -2.4e-05</velocity>
          <acceleration>-0.188627 0.004876 -0.087261 -0.33486 -1.31516 -0.020587</acceleration>
          <wrench>-0.018863 0.000488 -0.008726 0 -0 0</wrench>
        </link>
        <link name='zephyr_delta_wing::flap_left'>
          <pose>0.426679 0.341373 0.222937 -0.501879 -0.157583 0.040544</pose>
          <velocity>0.000154 5.3e-05 -0.001014 -0.000406 0.001776 -4.4e-05</velocity>
          <acceleration>0.116072 -0.030676 -0.85063 -0.420452 1.3061 -0.047457</acceleration>
          <wrench>0.011607 -0.003068 -0.085063 0 -0 0</wrench>
        </link>
        <link name='zephyr_delta_wing::flap_right'>
          <pose>-0.482519 0.341305 0.22293 -0.502175 0.157672 -0.040454</pose>
          <velocity>0.000333 0.000642 0.001639 0.028453 -0.007822 -4.1e-05</velocity>
          <acceleration>0.549097 1.3164 2.81307 -3.00922 -0.367776 -2.99637</acceleration>
          <wrench>0.05491 0.13164 0.281307 0 -0 0</wrench>
        </link>
        <link name='zephyr_delta_wing::propeller'>
          <pose>-0.027908 0.177181 0.242945 -0.006132 1.56837 -0.006063</pose>
          <velocity>0.000183 8.3e-05 -0.000106 -0.000508 1.5e-05 -4.2e-05</velocity>
          <acceleration>0.138045 -0.00775 -0.154055 -0.826125 0.006245 -0.107988</acceleration>
          <wrench>0.006902 -0.000387 -0.007703 0 -0 0</wrench>
        </link>
        <link name='zephyr_delta_wing::wing'>
          <pose>-0.027903 0.107181 0.234946 -1.5e-05 3e-06 6.9e-05</pose>
          <velocity>0.00017 7.9e-05 -7e-05 -0.000507 0.001738 -4.3e-05</velocity>
          <acceleration>0.125367 -0.01092 -0.080498 -0.38708 1.32368 -0.028827</acceleration>
          <wrench>0.18805 -0.016381 -0.120747 0 -0 0</wrench>
        </link>
        <link name='zephyr_delta_wing::zephyr/imu_link'>
          <pose>-0.027903 0.107181 0.234946 -1.5e-05 3e-06 6.9e-05</pose>
          <velocity>0.00017 7.9e-05 -7e-05 -0.000507 0.001738 -4.3e-05</velocity>
          <acceleration>0.128824 -0.010921 -0.126977 -0.387322 1.32368 -0.028823</acceleration>
          <wrench>0.019324 -0.001638 -0.019046 0 -0 0</wrench>
        </link>
      </model>
      <light name='sun'>
        <pose>0 0 10 0 -0 0</pose>
      </light>
    </state>
  </world>
</sdf>
